Workbook

Sheet 汇总
A1: 自动化调试收支情况
A2: 年份 | B2: 上游结算（按华源签报）约人工费用的70% | E2: 下游支出 | G2: 缺口 | I2: FTU调试 | J2: DTU调试
B3: 华源 | C3: 海翔 | D3: 设计院 （响水兴源） | E3: 公司支出 | F3: 协作支出 | I3: 534*0.7=373.8 | J3: 699.7*0.7=489.79
A4: 21年5-12月 | B4: =费用构成!F3 -> 70661.35 | C4: 0 | D4: 0 | E4: =费用构成!E11 -> 300600 | F4: 0 | G4: =B4+C4+D4-E4-F4 -> -229938.65 | I4: 华源签报358.14 | J4: 484.01
A5: 22年 | B5: =费用构成!F4 -> 116387.82 | C5: 0 | D5: 0 | E5: =费用构成!E12 -> 210800 | F5: =费用构成!F19 -> 472750 | G5: =B5+C5+D5-E5-F5 -> -567162.18
A6: 23年 | B6: =费用构成!F5 -> 185192.38 | C6: 0 | D6: 0 | E6: 0 | F6: =费用构成!F20 -> 778540 | G6: =B6+C6+D6-E6-F6 -> -593347.62
A7: 24年 | B7: =209*明细!B3+134*明细!C3 -> 139708.6 | C7: 0 | D7: =416*明细!B3+50*明细!C3 -> 173186.74 | E7: =费用构成!E13 -> 651340 | F7: =费用构成!F21 -> 355130 | G7: =B7+C7+D7-E7-F7 -> -693574.66
A8: 25年 | B8: =702*明细!B3+341*明细!C3 -> 416461.69 | C8: =420*明细!B3+174*明细!C3 -> 234636.54 | D8: =45*明细!B3+43*明细!C3 -> 36928.73 | E8: =费用构成!E14 -> 783680 | F8: =费用构成!F22 -> 250250 | G8: =B8+C8+D8-E8-F8 -> -345903.04
A9: 合计 | B9: =SUM(B4:B8) -> 928411.84 | C9: =SUM(C4:C8) -> 234636.54 | D9: =SUM(D4:D8) -> 210115.47 | E9: =SUM(E4:E8) -> 1946420 | F9: =SUM(F4:F8) -> 1856670 | G9: =SUM(G4:G8) -> -2429926.1
A10: 合计 | B10: 1373163.9 | E10: 3803090 | G10: -2429926.1
A12: 年份 | B12: 上游结算（按市公司结算价50%） | E12: 下游支出 | G12: 缺口 | I12: FTU调试 | J12: DTU调试
B13: 华源 | C13: 海翔 | D13: 设计院 （响水兴源） | E13: 公司支出 | F13: 协作支出 | I13: 1085.91*0.5=542.955 | J13: 1459.58*0.5=729.79
A14: 21年5-12月 | B14: =费用构成!D3 -> 106985.9 | C14: 0 | D14: 0 | E14: =费用构成!E11 -> 300600 | F14: 0 | G14: =B14+C14+D14-E14-F14 -> -193614.1
A15: 22年 | B15: =费用构成!D4 -> 176233.32 | C15: 0 | D15: 0 | E15: =费用构成!E12 -> 210800 | F15: =费用构成!F19 -> 472750 | G15: =B15+C15+D15-E15-F15 -> -507316.68
A16: 23年 | B16: =费用构成!D5 -> 280224.74 | C16: 0 | D16: 0 | E16: 0 | F16: =费用构成!F20 -> 778540 | G16: =B16+C16+D16-E16-F16 -> -498315.26
A17: 24年 | B17: =209*市公司结算!$E$6*0.5+134*市公司结算!$E$14*0.5 -> 211269.45 | C17: 0 | D17: =416*明细!B3+50*明细!C3 -> 173186.74 | E17: =费用构成!E13 -> 651340 | F17: =费用构成!F21 -> 355130 | G17: =B17+C17+D17-E17-F17 -> -622013.81
A18: 25年 | B18: =702*市公司结算!$E$6*0.5+341*市公司结算!$E$14*0.5 -> 630012.8 | C18: =420*市公司结算!$E$6*0.5+174*市公司结算!$E$14*0.5 -> 355024.56 | D18: =45*市公司结算!$E$6*0.5+43*市公司结算!$E$14*0.5 -> 55813.945 | E18: =费用构成!E14 -> 783680 | F18: =费用构成!F22 -> 250250 | G18: =B18+C18+D18-E18-F18 -> 6921.305
A19: 合计 | B19: =SUM(B14:B18) -> 1404726.2 | C19: =SUM(C14:C18) -> 355024.56 | D19: =SUM(D14:D18) -> 229000.68 | E19: =SUM(E14:E18) -> 1946420 | F19: =SUM(F14:F18) -> 1856670 | G19: =SUM(G14:G18) -> -1814338.5
A20: 合计 | B20: 1988751 | E20: 3803090 | G20: -1814338.5
A22: 年份 | B22: 上游结算（按市公司结算价70%） | E22: 下游支出 | G22: 缺口 | I22: FTU调试 | J22: DTU调试
B23: 华源 | C23: 海翔 | D23: 设计院 （响水兴源） | E23: 公司支出 | F23: 协作支出 | I23: 1085.91*0.7=760.137 | J23: 1459.58*0.7=1021.706
A24: 21年5-12月 | B24: =费用构成!E3 -> 149780.26 | C24: 0 | D24: 0 | E24: =费用构成!E11 -> 300600 | F24: 0 | G24: =B24+C24+D24-E24-F24 -> -150819.74
A25: 22年 | B25: =费用构成!E4 -> 246726.65 | C25: 0 | D25: 0 | E25: =费用构成!E12 -> 210800 | F25: =费用构成!F19 -> 472750 | G25: =B25+C25+D25-E25-F25 -> -436823.35
A26: 23年 | B26: =费用构成!E5 -> 392314.64 | C26: 0 | D26: 0 | E26: 0 | F26: =费用构成!F20 -> 778540 | G26: =B26+C26+D26-E26-F26 -> -386225.36
A27: 24年 | B27: =209*市公司结算!$E$6*0.7+134*市公司结算!$E$14*0.7 -> 295777.24 | C27: 0 | D27: =416*明细!B3+50*明细!C3 -> 173186.74 | E27: =费用构成!E13 -> 651340 | F27: =费用构成!F21 -> 355130 | G27: =B27+C27+D27-E27-F27 -> -537506.02
A28: 25年 | B28: =702*市公司结算!$E$6*0.7+341*市公司结算!$E$14*0.7 -> 882017.92 | C28: =420*市公司结算!$E$6*0.7+174*市公司结算!$E$14*0.7 -> 497034.38 | D28: =45*市公司结算!$E$6*0.7+43*市公司结算!$E$14*0.7 -> 78139.523 | E28: =费用构成!E14 -> 783680 | F28: =费用构成!F22 -> 250250 | G28: =B28+C28+D28-E28-F28 -> 423261.83
A29: 合计 | B29: =SUM(B24:B28) -> 1966616.7 | C29: =SUM(C24:C28) -> 497034.38 | D29: =SUM(D24:D28) -> 251326.26 | E29: =SUM(E24:E28) -> 1946420 | F29: =SUM(F24:F28) -> 1856670 | G29: =SUM(G24:G28) -> -1088112.7
A30: 合计 | B30: 2714977 | E30: 3803090 | G30: -1088112.6
A33: 年份 | B33: 上游结算（按照市场价FTU调试1000元一台、DTU1400元一台） | E33: 下游支出 | G33: 缺口 | I33: FTU调试 | J33: DTU调试
B34: 华源 | C34: 海翔 | D34: 设计院 （响水兴源） | E34: 公司支出 | F34: 协作支出 | I34: 1000 | J34: 1400
A35: 21年5-12月 | B35: 199000 | C35: 0 | D35: 0 | E35: 300600 | F35: 0 | G35: -101600
A36: 22年 | B36: 327600 | C36: 0 | D36: 0 | E36: 210800 | F36: 472750 | G36: -355950
A37: 23年 | B37: 523600 | C37: 0 | D37: 0 | E37: 0 | F37: 778540 | G37: -254940
A38: 24年 | B38: 396600 | C38: 0 | D38: 173186.74 | E38: 651340 | F38: 355130 | G38: -436683.26
A39: 25年 | B39: 1179400 | C39: 663600 | D39: 105200 | E39: 783680 | F39: 250250 | G39: 914270
A40: 合计 | B40: 2626200 | C40: 663600 | D40: 278386.74 | E40: 1946420 | F40: 1856670 | G40: -234903.26
A41: 合计 | B41: 3568186.7 | E41: 3803090 | G41: -234903.26
A45: 说明：1、21年5月起至今承接配电自动化终端调试任务。 2、24年响水兴源调试费用已结。

Sheet 费用构成
A1: 上游收入 | B1: 自动化数（台） | D1: 上游结算费用 （按市公司50%） | E1: 上游结算费用 （按市公司70%） | F1: 上游按华源签报结算费用 | G1: 按照市场价FTU调试1000元一台、DTU1400元一台 | H1: 备注
B2: FTU | C2: DTU
A3: 21年5-12月 | B3: =明细!B16 -> 150 | C3: =明细!D16 -> 35 | D3: =B3*市公司结算!$E$6*0.5+C3*市公司结算!$E$14*0.5 -> 106985.9 | E3: =B3*市公司结算!$E$6*0.7+C3*市公司结算!$E$14*0.7 -> 149780.26 | F3: =明细!F16 -> 70661.35 | G3: =B3*1000+C3*1400 -> 199000
A4: 22年 | B4: =明细!B29 -> 252 | C4: =明细!D29 -> 54 | D4: =B4*市公司结算!$E$6*0.5+C4*市公司结算!$E$14*0.5 -> 176233.32 | E4: =B4*市公司结算!$E$6*0.7+C4*市公司结算!$E$14*0.7 -> 246726.65 | F4: =明细!F29 -> 116387.82 | G4: =B4*1000+C4*1400 -> 327600
A5: 23年 | B5: =明细!B42 -> 336 | C5: =明细!D42 -> 134 | D5: =B5*市公司结算!$E$6*0.5+C5*市公司结算!$E$14*0.5 -> 280224.74 | E5: =B5*市公司结算!$E$6*0.7+C5*市公司结算!$E$14*0.7 -> 392314.64 | F5: =明细!F42 -> 185192.38 | G5: =B5*1000+C5*1400 -> 523600
A6: 24年 | B6: =明细!B55 -> 625 | C6: =明细!D55 -> 184 | D6: =B6*市公司结算!$E$6*0.5+C6*市公司结算!$E$14*0.5 -> 473628.23 | E6: =B6*市公司结算!$E$6*0.7+C6*市公司结算!$E$14*0.7 -> 663079.53 | F6: =明细!F55 -> 312895.34 | G6: =B6*1000+C6*1400 -> 882600 | H6: 2024年响水兴源调试FTU416台、DTU50台按华源签报结算173186.74元，按50%少结算89172.04元；按70%少结算194115.55元
A7: 25年 | B7: =明细!B68 -> 1167 | C7: =明细!D68 -> 558 | D7: =B7*市公司结算!$E$6*0.5+C7*市公司结算!$E$14*0.5 -> 1040851.3 | E7: =B7*市公司结算!$E$6*0.7+C7*市公司结算!$E$14*0.7 -> 1457191.8 | F7: =明细!F68 -> 688026.96 | G7: =B7*1000+C7*1400 -> 1948200
A8: 合计 | B8: =SUM(B3:B7) -> 2530 | C8: =SUM(C3:C7) -> 965 | D8: =SUM(D3:D7) -> 2077923.5 | E8: =SUM(E3:E7) -> 2909092.9 | F8: =SUM(F3:F7) -> 1373163.9 | G8: 3881000
A10: 盐开支出费用 | B10: 人员 | C10: 人员工资 | D10: 车辆费用 | E10: 累计
A11: 21年5-12月 | B11: 3 | C11: 268800 | D11: 31800 | E11: =C11+D11 -> 300600
A12: 22年1-6月 | B12: 3 | C12: 195200 | D12: 15600 | E12: =C12+D12 -> 210800
A13: 24年2-12月 | B13: 4-7 | C13: 586240 | D13: 65100 | E13: =C13+D13 -> 651340
A14: 25年全年 | B14: 6-7 | C14: 634880 | D14: 148800 | E14: =C14+D14 -> 783680
A15: 合计 | C15: =SUM(C11:C14) -> 1685120 | D15: =SUM(D11:D14) -> 261300 | E15: =SUM(E11:E14) -> 1946420
A17: 盐开协作 支出费用 | B17: 协作单位
B18: 大工天数 | C18: 小工天数 | D18: 人工费用 | E18: 车辆费用 | F18: 累计
A19: 22年7-12月 | B19: 620 | C19: 747 | D19: 385150 | E19: 87600 | F19: =D19+E19 -> 472750
A20: 23年 | B20: 1037 | C20: 1286 | D20: 653340 | E20: 125200 | F20: =D20+E20 -> 778540
A21: 24年 | B21: 414 | C21: 665 | D21: 298730 | E21: 56400 | F21: =D21+E21 -> 355130
A22: 25年4-12月 | B22: 325 | C22: 325 | D22: 185250 | E22: 65000 | F22: =D22+E22 -> 250250
A23: 合计 | B23: =SUM(B19:B22) -> 2396 | C23: =SUM(C19:C22) -> 3023 | D23: =SUM(D19:D22) -> 1522470 | E23: =SUM(E19:E22) -> 334200 | F23: =SUM(F19:F22) -> 1856670
A25: 注：1、24年前FTU和DTU调试、验收、质保需去施工队仓库和施工现场。 2、24年部分计划内FTU调试在盐开，FTU验收、FTU质保、DTU调试、DTU验收、DTU质保需去施工队仓库和施工现场。 3、25年以来FTU调试全部在盐开，其他工作内容同24年。

Sheet 明细
B1: 上游结算费用
A2: 调试单价 | B2: FTU一台 （元） | C2: DTU一台 （元） | F2: 下游 | G2: 调试大工 （元） | H2: 调试小工 （元） | I2: 公司车辆 | J2: 协作单位车辆
B3: 358.14 | C3: 484.01 | F3: 每天定额 | G3: 320 | H3: 250 | I3: 300 | J3: 200
B5: FTU数量（台） | D5: DTU数量（台） | F5: 上游可结算 （元） | G5: 下游费用 | R5: 应出勤天数
B6: 核对后数据 | C6: 收到计划任务 （已完成） | D6: 核对后数据 | E6: 收到计划任务 （已完成） | G6: 自有 | K6: 协作 | Q6: 费用合计
G7: 大工人数 | H7: 天数 | I7: 人工费用 | J7: 车辆 | K7: 大工人数 | L7: 天数 | M7: 小工人数 | N7: 天数 | O7: 人工费用 | P7: 车辆
A8: 44317 | B8: 44 | C8: 44 | D8: 2 | E8: 2 | F8: =B8*B3+D8*C3 -> 16726.18 | G8: =3+2 -> 5 | H8: =G8*R8 -> 95 | I8: =H8*G3 -> 30400 | J8: =R8*I3 -> 5700 | R8: 19
A9: 44348 | B9: 8 | C9: 8 | D9: 3 | F9: =B9*B3+D9*C3 -> 4317.15 | G9: =3+2 -> 5 | H9: =G9*R9 -> 105 | I9: =H9*G3 -> 33600 | J9: =(R9-10)*I3 -> 3300 | R9: 21
A10: 44378 | B10: 1 | C10: 1 | D10: 4 | E10: 7 | F10: =B10*B3+D10*C3 -> 2294.18 | G10: =3+2 -> 5 | H10: =G10*R10 -> 110 | I10: =H10*G3 -> 35200 | J10: =(R10-17)*I3 -> 1500 | R10: 22
A11: 44409 | B11: 41 | C11: 50 | D11: 13 | E11: 15 | F11: =B11*B3+D11*C3 -> 20975.87 | G11: =3+2 -> 5 | H11: =G11*R11 -> 110 | I11: =H11*G3 -> 35200 | J11: =R11*I3 -> 6600 | R11: 22
A12: 44440 | B12: 35 | C12: 38 | D12: 7 | E12: 7 | F12: =B12*B3+D12*C3 -> 15922.97 | G12: =3+2 -> 5 | H12: =G12*R12 -> 110 | I12: =H12*G3 -> 35200 | J12: =R12*I3 -> 6600 | R12: 22
A13: 44470 | B13: 8 | C13: 13 | D13: 2 | E13: 3 | F13: =B13*B3+D13*C3 -> 3833.14 | G13: =3+2 -> 5 | H13: =G13*R13 -> 85 | I13: =H13*G3 -> 27200 | J13: =(R13-7)*I3 -> 3000 | R13: 17
A14: 44501 | B14: 12 | C14: 13 | D14: 2 | E14: 3 | F14: =B14*B3+D14*C3 -> 5265.7 | G14: =3+2 -> 5 | H14: =G14*R14 -> 110 | I14: =H14*G3 -> 35200 | J14: =(R14-8)*I3 -> 4200 | R14: 22
A15: 44531 | B15: 1 | C15: 4 | D15: 2 | E15: 2 | F15: =B15*B3+D15*C3 -> 1326.16 | G15: =3+2 -> 5 | H15: =G15*R15 -> 115 | I15: =H15*G3 -> 36800 | J15: =(R15-20)*I3 -> 900 | R15: 23
A16: 21年合计 | B16: =SUM(B8:B15) -> 150 | C16: =SUM(C8:C15) -> 171 | D16: =SUM(D8:D15) -> 35 | E16: =SUM(E8:E15) -> 39 | F16: =SUM(F8:F15) -> 70661.35 | H16: =SUM(H8:H15) -> 840 | I16: =SUM(I8:I15) -> 268800 | J16: =SUM(J8:J15) -> 31800 | Q16: =I16+J16 -> 300600
A17: 44562 | B17: 4 | C17: 4 | D17: 2 | E17: 3 | F17: =B17*B3+D17*C3 -> 2400.58 | G17: =3+2 -> 5 | H17: =G17*R17 -> 105 | I17: =H17*G3 -> 33600 | J17: =(R17-15)*I3 -> 1800 | R17: 21
A18: 44593 | B18: 1 | C18: 1 | F18: =B18*B3+D18*C3 -> 358.14 | G18: =3+2 -> 5 | H18: =G18*R18 -> 80 | I18: =H18*G3 -> 25600 | J18: =(R18-15)*I3 -> 300 | R18: 16
A19: 44621 | B19: 6 | C19: 10 | E19: 1 | F19: =B19*B3+D19*C3 -> 2148.84 | G19: =3+2 -> 5 | H19: =G19*R19 -> 115 | I19: =H19*G3 -> 36800 | J19: =(R19-17)*I3 -> 1800 | R19: 23
A20: 44652 | B20: 8 | C20: 15 | E20: 7 | F20: =B20*B3+D20*C3 -> 2865.12 | G20: =3+2 -> 5 | H20: =G20*R20 -> 105 | I20: =H20*G3 -> 33600 | J20: =(R20-13)*I3 -> 2400 | R20: 21
A21: 44682 | B21: 11 | C21: 15 | D21: 11 | E21: 19 | F21: =B21*B3+D21*C3 -> 9263.65 | G21: =3+2 -> 5 | H21: =G21*R21 -> 100 | I21: =H21*G3 -> 32000 | J21: =R21*I3 -> 6000 | R21: 20
A22: 44713 | B22: 10 | C22: 10 | D22: 1 | E22: 3 | F22: =B22*B3+D22*C3 -> 4065.41 | G22: =3+2 -> 5 | H22: =G22*R22 -> 105 | I22: =H22*G3 -> 33600 | J22: =(R22-10)*I3 -> 3300 | R22: 21
A23: 44743 | B23: 5 | C23: 17 | D23: 3 | E23: 7 | F23: =B23*B3+D23*C3 -> 3242.73 | K23: 2 | L23: 22 | M23: 3 | N23: 43 | O23: =L23*G3+N23*H3 -> 17790 | P23: =(L23-14)*J3 -> 1600 | R23: 21
A24: 44774 | B24: 7 | C24: 13 | D24: 10 | E24: 15 | F24: =B24*B3+D24*C3 -> 7347.08 | K24: 3 | L24: 69 | M24: 4 | N24: 92 | O24: =L24*G3+N24*H3 -> 45080 | P24: =(L24-21)*J3 -> 9600 | R24: 23
A25: 44805 | B25: 30 | C25: 32 | D25: 5 | E25: 8 | F25: =B25*B3+D25*C3 -> 13164.25 | K25: 5 | L25: 120 | M25: 6 | N25: 141 | O25: =L25*G3+N25*H3 -> 73650 | P25: =(L25-35)*J3 -> 17000 | R25: 21
A26: 44835 | B26: 10 | C26: 13 | D26: 3 | E26: 3 | F26: =B26*B3+D26*C3 -> 5033.43 | K26: 2 | L26: 38 | M26: 3 | N26: 56 | O26: =L26*G3+N26*H3 -> 26160 | P26: =(L26-14)*J3 -> 4800 | R26: 18
A27: 44866 | B27: 82 | C27: 98 | D27: 8 | E27: 10 | F27: =B27*B3+D27*C3 -> 33239.56 | K27: 7 | L27: 182 | M27: 8 | N27: 204 | O27: =L27*G3+N27*H3 -> 109240 | P27: =(L27-49)*J3 -> 26600 | R27: 22
A28: 44896 | B28: 78 | C28: 80 | D28: 11 | E28: 24 | F28: =B28*B3+D28*C3 -> 33259.03 | K28: 7 | L28: 189 | M28: 8 | N28: 211 | O28: =L28*G3+N28*H3 -> 113230 | P28: =(L28-49)*J3 -> 28000 | R28: 22
A29: 22年合计 | B29: =SUM(B17:B28) -> 252 | C29: =SUM(C17:C28) -> 308 | D29: =SUM(D17:D28) -> 54 | E29: =SUM(E17:E28) -> 100 | F29: =SUM(F17:F28) -> 116387.82 | H29: =SUM(H17:H28) -> 610 | I29: =SUM(I17:I28) -> 195200 | J29: =SUM(J17:J28) -> 15600 | L29: =SUM(L23:L28) -> 620 | N29: =SUM(N23:N28) -> 747 | O29: =SUM(O23:O28) -> 385150 | P29: =SUM(P23:P28) -> 87600 | Q29: =I29+J29+O29+P29 -> 683550
A30: 44927 | B30: 9 | C30: 15 | D30: 24 | E30: 30 | F30: =B30*B3+D30*C3 -> 14839.5 | K30: 6 | L30: 120 | M30: 7 | N30: 138 | O30: =L30*G3+N30*H3 -> 72900 | P30: =(L30-48)*J3 -> 14400 | R30: 18
A31: 44958 | B31: 16 | C31: 22 | D31: 6 | E31: 7 | F31: =B31*B3+D31*C3 -> 8634.3 | K31: 3 | L31: 57 | M31: 4 | N31: 77 | O31: =L31*G3+N31*H3 -> 37490 | P31: =(L31-24)*J3 -> 6600 | R31: 20
A32: 44986 | B32: 42 | C32: 46 | D32: 9 | E32: 10 | F32: =B32*B3+D32*C3 -> 19397.97 | K32: 4 | L32: 100 | M32: 5 | N32: 123 | O32: =L32*G3+N32*H3 -> 62750 | P32: =(L32-32)*J3 -> 13600 | R32: 23
A33: 45017 | B33: 31 | C33: 31 | D33: 32 | E33: 34 | F33: =B33*B3+D33*C3 -> 26590.66 | K33: 7 | L33: 182 | M33: 8 | N33: 202 | O33: =L33*G3+N33*H3 -> 108740 | P33: =(L33-70)*J3 -> 22400 | R33: 20
A34: 45047 | B34: 28 | C34: 28 | D34: 13 | E34: 20 | F34: =B34*B3+D34*C3 -> 16320.05 | K34: 4 | L34: 84 | M34: 5 | N34: 105 | O34: =L34*G3+N34*H3 -> 53130 | P34: =(L34-32)*J3 -> 10400 | R34: 21
A35: 45078 | B35: 16 | C35: 18 | D35: 4 | E35: 4 | F35: =B35*B3+D35*C3 -> 7666.28 | K35: 3 | L35: 63 | M35: 4 | N35: 84 | O35: =L35*G3+N35*H3 -> 41160 | P35: =(L35-24)*J3 -> 7800 | R35: 21
A36: 45108 | B36: 6 | C36: 7 | D36: 1 | E36: 2 | F36: =B36*B3+D36*C3 -> 2632.85 | K36: 2 | L36: 22 | M36: 3 | N36: 43 | O36: =L36*G3+N36*H3 -> 17790 | P36: =(L36-16)*J3 -> 1200 | R36: 21
A37: 45139 | B37: 8 | C37: 8 | D37: 6 | E37: 6 | F37: =B37*B3+D37*C3 -> 5769.18 | K37: 2 | L37: 40 | M37: 3 | N37: 63 | O37: =L37*G3+N37*H3 -> 28550 | P37: =(L37-16)*J3 -> 4800 | R37: 23
A38: 45170 | B38: 52 | C38: 52 | D38: 13 | E38: 13 | F38: =B38*B3+D38*C3 -> 24915.41 | K38: 4 | L38: 92 | M38: 5 | N38: 112 | O38: =L38*G3+N38*H3 -> 57440 | P38: =(L38-32)*J3 -> 12000 | R38: 20
A39: 45200 | B39: 51 | C39: 53 | D39: 10 | E39: 11 | F39: =B39*B3+D39*C3 -> 23105.24 | K39: 4 | L39: 80 | M39: 5 | N39: 99 | O39: =L39*G3+N39*H3 -> 50350 | P39: =(L39-32)*J3 -> 9600 | R39: 19
A40: 45231 | B40: 70 | C40: 70 | D40: 16 | E40: 17 | F40: =B40*B3+D40*C3 -> 32813.96 | K40: 7 | L40: 182 | M40: 8 | N40: 204 | O40: =L40*G3+N40*H3 -> 109240 | P40: =(L40-77)*J3 -> 21000 | R40: 22
A41: 45261 | B41: 7 | C41: 7 | E41: 1 | F41: =B41*B3+D41*C3 -> 2506.98 | K41: 1 | L41: 15 | M41: 2 | N41: 36 | O41: =L41*G3+N41*H3 -> 13800 | P41: =(L41-8)*J3 -> 1400 | R41: 21
...

Sheet 市公司结算
A1: 1台FTU调试费用测算 | F1: 测算过程
F2: 直接费 | O2: 间接费 | R2: 利润(12.4) | S2: 编制基准期价差 | T2: 税金（9%） | U2: 合计
A3: 编制依据 | B3: 定额名称 | C3: 定额基价（元） | D3: 合计（元） | E3: 滚费后总计（元） | F3: 直接工程费 | J3: 措施费 | O3: 规费 | Q3: 企业管理费19.19
F4: 人工费 | G4: 材料费 | I4: 施工机械使用费 | J4: 冬雨季施工增加费(3.25) | K4: 夜间施工增加费 | L4: 施工工具用具使用费（2.03） | M4: 特殊地区施工增加费 | N4: 安全文明施工费（23.43） | O4: 社会保险费（27.3%） | P4: 住房公积金（12%）
G5: 计价材料费 | H5: 未计价材料费
A6: PX6-41 | B6: 配电装置系统调试 配电系统调试 10kV | C6: 366.86 | D6: =C6+C7 -> 534.09 | E6: =U6 -> 1085.91 | F6: 364.23 | H6: 0 | I6: 169.86 | J6: 0 | L6: 10.842027 | N6: 125.13729 | O6: 109.37827 | P6: 48.07836 | Q6: 102.49187 | R6: 66.22716 | T6: 89.662048 | U6: 1085.91
A7: PZ2-37 | B7: 配电自动化系统调试 主（子）站与终端联调 线路回路 2以下 | C7: 167.23
A9: 1台DTU调试费用测算 | F9: 测算过程
F10: 直接费 | O10: 间接费 | R10: 利润(12.4) | S10: 编制基准期价差 | T10: 税金（9%） | U10: 合计
A11: 编制依据 | B11: 定额名称 | C11: 定额基价（元） | D11: 合计（元） | E11: 滚费后总计（元） | F11: 直接工程费 | J11: 措施费 | O11: 规费 | Q11: 企业管理费19.19
F12: 人工费 | G12: 材料费 | I12: 施工机械使用费 | J12: 冬雨季施工增加费(3.25) | K12: 夜间施工增加费 | L12: 施工工具用具使用费（2.03） | M12: 特殊地区施工增加费 | N12: 安全文明施工费（23.43） | O12: 社会保险费（27.3%） | P12: 住房公积金（12%）
G13: 计价材料费 | H13: 未计价材料费
A14: PZ2-38 | B14: 配电自动化系统调试 主（子）站与终端联调 线路回路 6以下 | C14: 202.41 | D14: =C14+C15 -> 699.7 | E14: =U14 -> 1459.58 | F14: 580.8 | H14: 27.47 | I14: 91.43 | J14: 0 | L14: 13.646269 | N14: 157.50349 | O14: 174.41424 | P14: 76.6656 | Q14: 133.77377 | R14: 83.35652 | T14: 120.51539 | U14: 1459.58
A15: PZ2-2 | B15: 配电自动化设备 配电自动化终端装置安装调测 站所终端（DTU） 线路回数 6以内 | C15: 497.29
